Workbook

Sheet Questionnaire
C3: Remplissez les affirmations en indiquant les notes de 0 à 3 de la manière suivante :
C5: 3 = Toujours vrai / 2 = Souvent vrai / 1 = Parfois vrai / 0 = Jamais vrai
D6: Note
B7: 1 | C7: Je passe pour quelqu’un de coriace et les autres y regardent à deux fois avant de me marcher sur les pieds
B8: 2 | C8: Je sais garder mon calme en situation de conflit. Contrairement à d’autres, cela ne m’émeut pas
B9: 3 | C9: Je sens que j’ai une responsabilité morale à intervenir pour corriger les choses quand les gens font des erreurs
B11: 4 | C11: J’ai tendance à me sacrifier pour les autres et je me sens bien lorsque je leur consacre mon temps et mon énergie
B12: 5 | C12: J’aime que mes efforts soient payants et qu’ils m’apportent succès et reconnaissance
B13: 6 | C13: Je me sens différent des autres, étranger à la façon dont la plupart expriment leurs sentiments
B15: 7 | C15: Je suis une personne indépendante qui tient particulièrement à sa vie privée et à avoir du temps pour elle
B16: 8 | C16: Quand j’ai des décisions importantes à prendre, je demande l’avis des autres, car ce genre de situations m’insécurise
B17: 9 | C17: Je me sens frustré par les règles qui n’ont pas lieu d’être, par les limitations et par le fait de risquer de passer à côté d’opportunités intéressantes
B19: 10 | C19: C’est important pour moi d’éprouver un sentiment d’union avec les autres et d’éviter les conflits
B20: 11 | C20: Je sais comment les choses doivent être faites et je ne tolère pas l’imperfection, à commencer par ce qui me concerne
B21: 12 | C21: Je consacre volontiers mon temps libre à aider les autres et je trouve gratifiant de sentir qu’ils ont besoin de moi
... B37: 24 | C37: Je suis prudent et je me sens anxieux lorsque je dois prendre d’importantes décisions sans le soutien des autres
A39: < | B39: 25 | C39: Ca m’est égal d’être excessif ou de faire entorse à certaines règles, si cela peut me permettre de vivre différentes situations excitantes
B40: 26 | C40: J’ai confiance en ma force et en mon courage. Lorsque vient le moment de prendre position je ne fais pas de compromis
B41: 27 | C41: Je suis prêt à faire tout mon possible pour éviter les discussions houleuses ou les conflits
B43: 28 | C43: Je suis un négociateur coriace et comme je sais prendre le contrôle des situations, j’en sors généralement gagnant
B44: 29 | C44: Je suis ambitieux et je me pousse pour réaliser mes objectifs
B45: 30 | C45: Je me lance souvent dans de nouveaux projets ou de nouvelles aventures avant même que ceux qui sont en cours ne soient terminés
B47: 31 | C47: Je suis un être unique et souvent incompris des autres
B48: 32 | C48: Je tiens tellement à vivre de façon tranquille et harmonieuse que j’ai parfois tendance à me voiler la face à propos de problèmes pourtant sérieux
B49: 33 | C49: Je préfère me tenir à l’écart et observer les autres plutôt que de me trouver pris dans des conversations superficielles ou dans leurs problèmes émotionnels
B51: 34 | C51: Je veux tenir une place importante dans la vie des autres. Savoir qu’ils ont besoin de moi est important pour mon bonheur
B52: 35 | C52: Je fais tout pour être efficace, parfait et au-dessus de toute critique.
B53: 36 | C53: Il y a toujours quelque chose qui me préoccupe ou m’inquiète
B55: 37 | C55: Lorsque trop de choix s’offrent à moi, j’ai du mal à rester centré et à ne pas me disperser
... B159: 115 | C159: Exceller dans ce que je fais et être reconnu pour mes succès est très important pour moi
A160: < | B160: 116 | C160: Je suis parfois soupçonneux quant aux motivations des autres ; je scrute l’environnement pour prévenir un éventuel danger
A161: T ** | B161: 117 | C161: Je m’attache à ce qui est familier, la routine me convient et je désire vivre de façon harmonieuse dans un environnement stable
B163: 118 | C163: Je suis plus méfiant que la plupart des gens et je sais mieux qu’eux sentir le danger et détecter les situations menaçantes
B164: 119 | C164: J’ai du mal à me donner des priorités ou à me centrer sur des décisions précises parce que tous les points de vue me semblent intéressants
B165: 120 | C165: Même si je suis déprimé ou sous pression, c’est très important pour moi de donner aux autres l’image d’une personne sûre d’elle
B167: 121 | C167: Je passe de temps à fantasmer et à raviver des sentiments nostalgiques ayant trait à des moments du passé
B168: 122 | C168: J’ai tendance à penser que si « un peu c’est bien, alors beaucoup c’est encore mieux » et du coup à être excessif dans certains domaines
B169: 123 | C169: Je suis critique avec les autres lorsqu’ils sont imprécis, inefficaces, ou qu’ils ne suivent pas la direction attendue
B171: 124 | C171: Je cloisonne mes relations (travail, famille, sport, hobbies…). La plupart des personnes que je rencontre dans ces domaines ne se connaissent pas entre elles
B172: 125 | C172: J’ai du respect pour le courage et la force ainsi que pour la capacité à utiliser son pouvoir lorsqu’il le faut
...

Sheet Résultat
C2: A | F2: B | I2: C | L2: D | O2: E | R2: F | U2: G | X2: H | AA2: I
B4: 1 | C4: =Questionnaire!D7 -> 0 | E4: 2 | F4: =Questionnaire!D8 -> 0 | H4: 3 | I4: =Questionnaire!D9 -> 0 | K4: 4 | L4: =Questionnaire!D11 -> 0 | N4: 5 | O4: =Questionnaire!D12 -> 0 | Q4: 6 | R4: =Questionnaire!D13 -> 0 | T4: 7 | U4: =Questionnaire!D15 -> 0 | W4: 8 | X4: =Questionnaire!D16 -> 0 | Z4: 9 | AA4: =Questionnaire!D17 -> 0
B5: 18 | C5: =Questionnaire!D29 -> 0 | E5: 10 | F5: =Questionnaire!D19 -> 0 | H5: 11 | I5: =Questionnaire!D20 -> 0 | K5: 12 | L5: =Questionnaire!D21 -> 0 | N5: 13 | O5: =Questionnaire!D23 -> 0 | Q5: 14 | R5: =Questionnaire!D24 -> 0 | T5: 15 | U5: =Questionnaire!D25 -> 0 | W5: 16 | X5: =Questionnaire!D27 -> 0 | Z5: 17 | AA5: =Questionnaire!D28 -> 0
B6: 26 | C6: =Questionnaire!D40 -> 0 | E6: 27 | F6: =Questionnaire!D41 -> 0 | H6: 19 | I6: =Questionnaire!D31 -> 0 | K6: 20 | L6: =Questionnaire!D32 -> 0 | N6: 21 | O6: =Questionnaire!D33 -> 0 | Q6: 22 | R6: =Questionnaire!D35 -> 0 | T6: 23 | U6: =Questionnaire!D36 -> 0 | W6: 24 | X6: =Questionnaire!D37 -> 0 | Z6: 25 | AA6: =Questionnaire!D39 -> 0
B8: 28 | C8: =Questionnaire!D43 -> 0 | E8: 32 | F8: =Questionnaire!D48 -> 0 | H8: 35 | I8: =Questionnaire!D52 -> 0 | K8: 34 | L8: =Questionnaire!D51 -> 0 | N8: 29 | O8: =Questionnaire!D44 -> 0 | Q8: 31 | R8: =Questionnaire!D47 -> 0 | T8: 33 | U8: =Questionnaire!D49 -> 0 | W8: 36 | X8: =Questionnaire!D53 -> 0 | Z8: 30 | AA8: =Questionnaire!D45 -> 0
B9: 45 | C9: =Questionnaire!D65 -> 0 | E9: 37 | F9: =Questionnaire!D55 -> 0 | H9: 41 | I9: =Questionnaire!D60 -> 0 | K9: 42 | L9: =Questionnaire!D61 -> 0 | N9: 43 | O9: =Questionnaire!D63 -> 0 | Q9: 38 | R9: =Questionnaire!D56 -> 0 | T9: 39 | U9: =Questionnaire!D57 -> 0 | W9: 40 | X9: =Questionnaire!D59 -> 0 | Y9: 0 | Z9: 44 | AA9: =Questionnaire!D64 -> 0
B10: 49 | C10: =Questionnaire!D71 -> 0 | E10: 54 | F10: =Questionnaire!D77 -> 0 | H10: 46 | I10: =Questionnaire!D67 -> 0 | K10: 47 | L10: =Questionnaire!D68 -> 0 | N10: 51 | O10: =Questionnaire!D73 -> 0 | Q10: 52 | R10: =Questionnaire!D75 -> 0 | T10: 53 | U10: =Questionnaire!D76 -> 0 | W10: 48 | X10: =Questionnaire!D69 -> 0 | Z10: 50 | AA10: =Questionnaire!D72 -> 0
B12: 60 | C12: =Questionnaire!D85 -> 0 | E12: 62 | F12: =Questionnaire!D88 -> 0 | H12: 57 | I12: =Questionnaire!D81 -> 0 | K12: 61 | L12: =Questionnaire!D87 -> 0 | N12: 56 | O12: =Questionnaire!D80 -> 0 | Q12: 58 | R12: =Questionnaire!D83 -> 0 | T12: 55 | U12: =Questionnaire!D79 -> 0 | W12: 59 | X12: =Questionnaire!D84 -> 0 | Z12: 63 | AA12: =Questionnaire!D89 -> 0
B13: 64 | C13: =Questionnaire!D91 -> 0 | E13: 68 | F13: =Questionnaire!D96 -> 0 | H13: 71 | I13: =Questionnaire!D100 -> 0 | K13: 69 | L13: =Questionnaire!D97 -> 0 | N13: 70 | O13: =Questionnaire!D99 -> 0 | Q13: 65 | R13: =Questionnaire!D92 -> 0 | T13: 72 | U13: =Questionnaire!D101 -> 0 | W13: 66 | X13: =Questionnaire!D93 -> 0 | Z13: 67 | AA13: =Questionnaire!D95 -> 0
B14: 80 | C14: =Questionnaire!D112 -> 0 | E14: 75 | F14: =Questionnaire!D105 -> 0 | H14: 77 | I14: =Questionnaire!D108 -> 0 | K14: 73 | L14: =Questionnaire!D103 -> 0 | N14: 78 | O14: =Questionnaire!D109 -> 0 | Q14: 79 | R14: =Questionnaire!D111 -> 0 | T14: 76 | U14: =Questionnaire!D107 -> 0 | W14: 81 | X14: =Questionnaire!D113 -> 0 | Z14: 74 | AA14: =Questionnaire!D104 -> 0
B16: 87 | C16: =Questionnaire!D121 -> 0 | E16: 90 | F16: =Questionnaire!D125 -> 0 | H16: 82 | I16: =Questionnaire!D115 -> 0 | K16: 85 | L16: =Questionnaire!D119 -> 0 | N16: 88 | O16: =Questionnaire!D123 -> 0 | Q16: 83 | R16: =Questionnaire!D116 -> 0 | T16: 86 | U16: =Questionnaire!D120 -> 0 | W16: 89 | X16: =Questionnaire!D124 -> 0 | Z16: 84 | AA16: =Questionnaire!D117 -> 0
B17: 98 | C17: =Questionnaire!D136 -> 0 | E17: 92 | F17: =Questionnaire!D128 -> 0 | H17: 96 | I17: =Questionnaire!D133 -> 0 | K17: 99 | L17: =Questionnaire!D137 -> 0 | N17: 93 | O17: =Questionnaire!D129 -> 0 | Q17: 94 | R17: =Questionnaire!D131 -> 0 | T17: 97 | U17: =Questionnaire!D135 -> 0 | W17: 91 | X17: =Questionnaire!D127 -> 0 | Z17: 95 | AA17: =Questionnaire!D132 -> 0
B18: 101 | C18: =Questionnaire!D140 -> 0 | E18: 102 | F18: =Questionnaire!D141 -> 0 | H18: 100 | I18: =Questionnaire!D139 -> 0 | K18: 103 | L18: =Questionnaire!D143 -> 0 | N18: 105 | O18: =Questionnaire!D145 -> 0 | Q18: 104 | R18: =Questionnaire!D144 -> 0 | T18: 106 | U18: =Questionnaire!D147 -> 0 | W18: 108 | X18: =Questionnaire!D149 -> 0 | Z18: 107 | AA18: =Questionnaire!D148 -> 0
B20: 114 | C20: =Questionnaire!D157 -> 0 | E20: 117 | F20: =Questionnaire!D161 -> 0 | H20: 109 | I20: =Questionnaire!D151 -> 0 | K20: 112 | L20: =Questionnaire!D155 -> 0 | N20: 115 | O20: =Questionnaire!D159 -> 0 | Q20: 110 | R20: =Questionnaire!D152 -> 0 | T20: 113 | U20: =Questionnaire!D156 -> 0 | W20: 116 | X20: =Questionnaire!D160 -> 0 | Z20: 111 | AA20: =Questionnaire!D153 -> 0
B21: 125 | C21: =Questionnaire!D172 -> 0 | E21: 119 | F21: =Questionnaire!D164 -> 0 | H21: 123 | I21: =Questionnaire!D169 -> 0 | K21: 126 | L21: =Questionnaire!D173 -> 0 | N21: 120 | O21: =Questionnaire!D165 -> 0 | Q21: 121 | R21: =Questionnaire!D167 -> 0 | T21: 124 | U21: =Questionnaire!D171 -> 0 | W21: 118 | X21: =Questionnaire!D163 -> 0 | Z21: 122 | AA21: =Questionnaire!D168 -> 0
B22: 128 | C22: =Questionnaire!D176 -> 0 | E22: 129 | F22: =Questionnaire!D177 -> 0 | H22: 127 | I22: =Questionnaire!D175 -> 0 | K22: 130 | L22: =Questionnaire!D179 -> 0 | N22: 132 | O22: =Questionnaire!D181 -> 0 | Q22: 131 | R22: =Questionnaire!D180 -> 0 | T22: 133 | U22: =Questionnaire!D183 -> 0 | W22: 135 | X22: =Questionnaire!D185 -> 0 | Z22: 134 | AA22: =Questionnaire!D184 -> 0 | AC22: Profil
B25: 8 | C25: =SUM(C4:C22) -> 0 | E25: 9 | F25: =SUM(F4:F22) -> 0 | H25: 1 | I25: =SUM(I4:I22) -> 0 | K25: 2 | L25: =SUM(L4:L22) -> 0 | N25: 3 | O25: =SUM(O4:O22) -> 0 | Q25: 4 | R25: =SUM(R4:R22) -> 0 | T25: 5 | U25: =SUM(U4:U22) -> 0 | W25: 6 | X25: =SUM(X4:X22) -> 0 | Z25: 7 | AA25: =SUM(AA4:AA22) -> 0
AC26: 9- Médiateur | AD26: =AE26/$AE$37 -> #DIV/0! | AE26: =F25 -> 0
AC27: 1- Perfectionniste | AD27: =AE27/$AE$37 -> #DIV/0! | AE27: =I25 -> 0
AC28: 2- Aidant | AD28: =AE28/$AE$37 -> #DIV/0! | AE28: =L25 -> 0
AC29: 3- Compétiteur | AD29: =AE29/$AE$37 -> #DIV/0! | AE29: =O25 -> 0
AC30: 4- Artiste | AD30: =AE30/$AE$37 -> #DIV/0! | AE30: =R25 -> 0
AC31: 5- Penseur | AD31: =AE31/$AE$37 -> #DIV/0! | AE31: =U25 -> 0
AC32: 6- Loyaliste | AD32: =AE32/$AE$37 -> #DIV/0! | AE32: =X25 -> 0
AC33: 7- Jouisseur | AD33: =AE33/$AE$37 -> #DIV/0! | AE33: =AA25 -> 0
AC34: 8- Leader | AD34: =AE34/$AE$37 -> #DIV/0! | AE34: =C25 -> 0
AD37: =SUM(AD26:AD34) -> #DIV/0! | AE37: =SUM(AE26:AE34) -> 0

Sheet Feuil1
